Workbook

Sheet Sales
A1: OrderID | B1: OrderDate | C1: Region | D1: Salesperson | E1: Channel | F1: Category | G1: Product | H1: Units | I1: UnitPrice | J1: Discount | K1: GrossRevenue | L1: DiscountAmount | M1: NetRevenue | N1: RoundedNetRevenue | O1: RoundUpNetRevenue | P1: RoundDownNetRevenue
A2: ORD-1001 | B2: 45829 | C2: North | D2: Priya Nair | E2: Online | F2: Electronics | G2: Wireless Mouse | H2: 6 | I2: 1500 | J2: 0 | K2: =H2*I2 | L2: =H2*I2*J2 | M2: =H2*I2*(1-J2) | N2: =ROUND(H2*I2*(1-J2),0) | O2: =ROUNDUP(H2*I2*(1-J2),0) | P2: =ROUNDDOWN(H2*I2*(1-J2),0)
A3: ORD-1002 | B3: 45953 | C3: North | D3: Priya Nair | E3: Retail Store | F3: Furniture | G3: Filing Cabinet | H3: 25 | I3: 7000 | J3: 0 | K3: =H3*I3 | L3: =H3*I3*J3 | M3: =H3*I3*(1-J3) | N3: =ROUND(H3*I3*(1-J3),0) | O3: =ROUNDUP(H3*I3*(1-J3),0) | P3: =ROUNDDOWN(H3*I3*(1-J3),0)
A4: ORD-1003 | B4: 45831 | C4: West | D4: Ananya Joshi | E4: Retail Store | F4: Stationery | G4: Gel Pen Pack | H4: 24 | I4: 250 | J4: 0 | K4: =H4*I4 | L4: =H4*I4*J4 | M4: =H4*I4*(1-J4) | N4: =ROUND(H4*I4*(1-J4),0) | O4: =ROUNDUP(H4*I4*(1-J4),0) | P4: =ROUNDDOWN(H4*I4*(1-J4),0)
A5: ORD-1004 | B5: 45943 | C5: South | D5: Rahul Iyer | E5: Retail Store | F5: Furniture | G5: Standing Desk | H5: 5 | I5: 24000 | J5: 0.1 | K5: =H5*I5 | L5: =H5*I5*J5 | M5: =H5*I5*(1-J5) | N5: =ROUND(H5*I5*(1-J5),0) | O5: =ROUNDUP(H5*I5*(1-J5),0) | P5: =ROUNDDOWN(H5*I5*(1-J5),0)
A6: ORD-1005 | B6: 45674 | C6: East | D6: Kabir Das | E6: Retail Store | F6: Electronics | G6: Noise Cancel Headset | H6: 22 | I6: 8500 | J6: 0 | K6: =H6*I6 | L6: =H6*I6*J6 | M6: =H6*I6*(1-J6) | N6: =ROUND(H6*I6*(1-J6),0) | O6: =ROUNDUP(H6*I6*(1-J6),0) | P6: =ROUNDDOWN(H6*I6*(1-J6),0)
A7: ORD-1006 | B7: 45868 | C7: West | D7: Vikram Shah | E7: Partner | F7: Electronics | G7: Noise Cancel Headset | H7: 25 | I7: 8500 | J7: 0 | K7: =H7*I7 | L7: =H7*I7*J7 | M7: =H7*I7*(1-J7) | N7: =ROUND(H7*I7*(1-J7),0) | O7: =ROUNDUP(H7*I7*(1-J7),0) | P7: =ROUNDDOWN(H7*I7*(1-J7),0)
A8: ORD-1007 | B8: 46013 | C8: East | D8: Meera Sen | E8: Retail Store | F8: Stationery | G8: Gel Pen Pack | H8: 15 | I8: 250 | J8: 0 | K8: =H8*I8 | L8: =H8*I8*J8 | M8: =H8*I8*(1-J8) | N8: =ROUND(H8*I8*(1-J8),0) | O8: =ROUNDUP(H8*I8*(1-J8),0) | P8: =ROUNDDOWN(H8*I8*(1-J8),0)
A9: ORD-1008 | B9: 45858 | C9: South | D9: Sneha Rao | E9: Partner | F9: Electronics | G9: Wireless Mouse | H9: 6 | I9: 1500 | J9: 0 | K9: =H9*I9 | L9: =H9*I9*J9 | M9: =H9*I9*(1-J9) | N9: =ROUND(H9*I9*(1-J9),0) | O9: =ROUNDUP(H9*I9*(1-J9),0) | P9: =ROUNDDOWN(H9*I9*(1-J9),0)
A10: ORD-1009 | B10: 45838 | C10: South | D10: Rahul Iyer | E10: Retail Store | F10: Stationery | G10: Notebook Set | H10: 8 | I10: 600 | J10: 0.15 | K10: =H10*I10 | L10: =H10*I10*J10 | M10: =H10*I10*(1-J10) | N10: =ROUND(H10*I10*(1-J10),0) | O10: =ROUNDUP(H10*I10*(1-J10),0) | P10: =ROUNDDOWN(H10*I10*(1-J10),0)
A11: ORD-1010 | B11: 45679 | C11: East | D11: Kabir Das | E11: Partner | F11: Furniture | G11: Filing Cabinet | H11: 7 | I11: 7000 | J11: 0.05 | K11: =H11*I11 | L11: =H11*I11*J11 | M11: =H11*I11*(1-J11) | N11: =ROUND(H11*I11*(1-J11),0) | O11: =ROUNDUP(H11*I11*(1-J11),0) | P11: =ROUNDDOWN(H11*I11*(1-J11),0)
A12: ORD-1011 | B12: 45872 | C12: West | D12: Vikram Shah | E12: Online | F12: Electronics | G12: Laptop Pro 14 | H12: 12 | I12: 95000 | J12: 0.1 | K12: =H12*I12 | L12: =H12*I12*J12 | M12: =H12*I12*(1-J12) | N12: =ROUND(H12*I12*(1-J12),0) | O12: =ROUNDUP(H12*I12*(1-J12),0) | P12: =ROUNDDOWN(H12*I12*(1-J12),0)
A13: ORD-1012 | B13: 45817 | C13: North | D13: Priya Nair | E13: Retail Store | F13: Electronics | G13: Laptop Pro 14 | H13: 5 | I13: 95000 | J13: 0.15 | K13: =H13*I13 | L13: =H13*I13*J13 | M13: =H13*I13*(1-J13) | N13: =ROUND(H13*I13*(1-J13),0) | O13: =ROUNDUP(H13*I13*(1-J13),0) | P13: =ROUNDDOWN(H13*I13*(1-J13),0)
... A121: ORD-1120 | B121: 45878 | C121: South | D121: Sneha Rao | E121: Retail Store | F121: Stationery | G121: Gel Pen Pack | H121: 2 | I121: 250 | J121: 0 | K121: =H121*I121 | L121: =H121*I121*J121 | M121: =H121*I121*(1-J121) | N121: =ROUND(H121*I121*(1-J121),0) | O121: =ROUNDUP(H121*I121*(1-J121),0) | P121: =ROUNDDOWN(H121*I121*(1-J121),0)

Sheet Products
A1: Product | B1: Category | C1: UnitPrice | D1: UnitCost
A2: Laptop Pro 14 | B2: Electronics | C2: 95000 | D2: 65726
A3: Wireless Mouse | B3: Electronics | C3: 1500 | D3: 954
A4: Noise Cancel Headset | B4: Electronics | C4: 8500 | D4: 4714
A5: Office Chair | B5: Furniture | C5: 12000 | D5: 8805
A6: Standing Desk | B6: Furniture | C6: 24000 | D6: 13587
A7: Filing Cabinet | B7: Furniture | C7: 7000 | D7: 4582
A8: A4 Paper Ream | B8: Stationery | C8: 350 | D8: 259
A9: Gel Pen Pack | B9: Stationery | C9: 250 | D9: 143
A10: Notebook Set | B10: Stationery | C10: 600 | D10: 419

Sheet Targets
A1: Region | B1: Salesperson | C1: MonthlyTarget
A2: North | B2: Aarav Mehta | C2: 300000
A3: North | B3: Priya Nair | C3: 250000
A4: South | B4: Rahul Iyer | C4: 150000
A5: South | B5: Sneha Rao | C5: 300000
A6: East | B6: Kabir Das | C6: 150000
A7: East | B7: Meera Sen | C7: 200000
A8: West | B8: Vikram Shah | C8: 300000
A9: West | B9: Ananya Joshi | C9: 150000

Sheet Charts
A1: Sales Dashboard
A3: Monthly Net Revenue | D3: Net Revenue by Region | G3: Net Revenue by Category
A4: Month | B4: Net Revenue | D4: Region | E4: Net Revenue | G4: Category | H4: Net Revenue
A5: 45658 | B5: 2631775 | D5: North | E5: 5300280 | G5: Electronics | H5: 11912375
A6: 45689 | B6: 678050 | D6: South | E6: 3712480 | G6: Furniture | H6: 6653000
A7: 45717 | B7: 3360925 | D7: East | E7: 5853755 | G7: Stationery | H7: 179860
A8: 45748 | B8: 1417700 | D8: West | E8: 3878720
A9: 45778 | B9: 1129620
A10: 45809 | B10: 2216930
A11: 45839 | B11: 460140
A12: 45870 | B12: 2345135
A13: 45901 | B13: 1818600
A14: 45931 | B14: 1193950
A15: 45962 | B15: 808425
A16: 45992 | B16: 683985

Sheet Analysis
A1: Sales Analysis | E1: East Units Helper | F1: East Units Helper
E2: =IF(Sales!C2="East",Sales!H2,"") | F2: =IF(Sales!C2="East",Sales!H2,"")
A3: 2. Aggregation | E3: =IF(Sales!C3="East",Sales!H3,"") | F3: =IF(Sales!C3="East",Sales!H3,"")
A4: Metric | B4: Formula | C4: Result | E4: =IF(Sales!C4="East",Sales!H4,"") | F4: =IF(Sales!C4="East",Sales!H4,"")
A5: Total Units | B5: =SUM(Sales!H2:H121) | C5: =SUM(Sales!H2:H121) | E5: =IF(Sales!C5="East",Sales!H5,"") | F5: =IF(Sales!C5="East",Sales!H5,"")
A6: Average Units | B6: =AVERAGE(Sales!H2:H121) | C6: =AVERAGE(Sales!H2:H121) | E6: =IF(Sales!C6="East",Sales!H6,"") | F6: =IF(Sales!C6="East",Sales!H6,"")
A7: Minimum Units | B7: =MIN(Sales!H2:H121) | C7: =MIN(Sales!H2:H121) | E7: =IF(Sales!C7="East",Sales!H7,"") | F7: =IF(Sales!C7="East",Sales!H7,"")
A8: Maximum Units | B8: =MAX(Sales!H2:H121) | C8: =MAX(Sales!H2:H121) | E8: =IF(Sales!C8="East",Sales!H8,"") | F8: =IF(Sales!C8="East",Sales!H8,"")
A9: Median Units | B9: =MEDIAN(Sales!H2:H121) | C9: =MEDIAN(Sales!H2:H121) | E9: =IF(Sales!C9="East",Sales!H9,"") | F9: =IF(Sales!C9="East",Sales!H9,"")
A10: Most Frequent Units | B10: =MODE(Sales!H2:H121) | C10: =MODE(Sales!H2:H121) | E10: =IF(Sales!C10="East",Sales!H10,"") | F10: =IF(Sales!C10="East",Sales!H10,"")
A11: Numeric Unit Count | B11: =COUNT(Sales!H2:H121) | C11: =COUNT(Sales!H2:H121) | E11: =IF(Sales!C11="East",Sales!H11,"") | F11: =IF(Sales!C11="East",Sales!H11,"")
A12: Non-blank OrderID Count | B12: =COUNTA(Sales!A2:A121) | C12: =COUNTA(Sales!A2:A121) | E12: =IF(Sales!C12="East",Sales!H12,"") | F12: =IF(Sales!C12="East",Sales!H12,"")
A13: Blank OrderID Count | B13: =COUNTBLANK(Sales!A2:A121) | C13: =COUNTBLANK(Sales!A2:A121) | E13: =IF(Sales!C13="East",Sales!H13,"") | F13: =IF(Sales!C13="East",Sales!H13,"")
A14: Third-largest Units | B14: =LARGE(Sales!H2:H121,3) | C14: =LARGE(Sales!H2:H121,3) | E14: =IF(Sales!C14="East",Sales!H14,"") | F14: =IF(Sales!C14="East",Sales!H14,"")
A15: Third-smallest Units | B15: =SMALL(Sales!H2:H121,3) | C15: =SMALL(Sales!H2:H121,3) | E15: =IF(Sales!C15="East",Sales!H15,"") | F15: =IF(Sales!C15="East",Sales!H15,"")
A16: Visible Units Subtotal | B16: =SUBTOTAL(109,Sales!H2:H121) | C16: =SUBTOTAL(109,Sales!H2:H121) | E16: =IF(Sales!C16="East",Sales!H16,"") | F16: =IF(Sales!C16="East",Sales!H16,"")
E17: =IF(Sales!C17="East",Sales!H17,"") | F17: =IF(Sales!C17="East",Sales!H17,"")
E18: =IF(Sales!C18="East",Sales!H18,"") | F18: =IF(Sales!C18="East",Sales!H18,"")
A19: 3. Conditional Aggregation | E19: =IF(Sales!C19="East",Sales!H19,"") | F19: =IF(Sales!C19="East",Sales!H19,"")
A20: Metric | B20: Formula | C20: Result | E20: =IF(Sales!C20="East",Sales!H20,"") | F20: =IF(Sales!C20="East",Sales!H20,"")
A21: North Total Units | B21: =SUMIF(Sales!C2:C121,"North",Sales!H2:H121) | C21: =SUMIF(Sales!C2:C121,"North",Sales!H2:H121) | E21: =IF(Sales!C21="East",Sales!H21,"") | F21: =IF(Sales!C21="East",Sales!H21,"")
A22: North Electronics Units | B22: =SUMIFS(Sales!H2:H121,Sales!C2:C121,"North",Sales!F2:F121,"Electronics") | C22: =SUMIFS(Sales!H2:H121,Sales!C2:C121,"North",Sales!F2:F121,"Electronics") | E22: =IF(Sales!C22="East",Sales!H22,"") | F22: =IF(Sales!C22="East",Sales!H22,"")
A23: Furniture Order Count | B23: =COUNTIF(Sales!F2:F121,"Furniture") | C23: =COUNTIF(Sales!F2:F121,"Furniture") | E23: =IF(Sales!C23="East",Sales!H23,"") | F23: =IF(Sales!C23="East",Sales!H23,"")
A24: West Online Order Count | B24: =COUNTIFS(Sales!C2:C121,"West",Sales!E2:E121,"Online") | C24: =COUNTIFS(Sales!C2:C121,"West",Sales!E2:E121,"Online") | E24: =IF(Sales!C24="East",Sales!H24,"") | F24: =IF(Sales!C24="East",Sales!H24,"")
A25: North Average Units | B25: =AVERAGEIF(Sales!C2:C121,"North",Sales!H2:H121) | C25: =AVERAGEIF(Sales!C2:C121,"North",Sales!H2:H121) | E25: =IF(Sales!C25="East",Sales!H25,"") | F25: =IF(Sales!C25="East",Sales!H25,"")
A26: North Electronics Average Units | B26: =AVERAGEIFS(Sales!H2:H121,Sales!C2:C121,"North",Sales!F2:F121,"Electronics") | C26: =AVERAGEIFS(Sales!H2:H121,Sales!C2:C121,"North",Sales!F2:F121,"Electronics") | E26: =IF(Sales!C26="East",Sales!H26,"") | F26: =IF(Sales!C26="East",Sales!H26,"")
A27: East Maximum Units | B27: =MAX(E2:E121) | C27: =MAX(E2:E121) | E27: =IF(Sales!C27="East",Sales!H27,"") | F27: =IF(Sales!C27="East",Sales!H27,"")
A28: East Minimum Units | B28: =MIN(F2:F121) | C28: =MIN(F2:F121) | E28: =IF(Sales!C28="East",Sales!H28,"") | F28: =IF(Sales!C28="East",Sales!H28,"")
A29: South Gross Revenue | B29: =SUMPRODUCT((Sales!C2:C121="South")*Sales!H2:H121*Sales!I2:I121) | C29: =SUMPRODUCT((Sales!C2:C121="South")*Sales!H2:H121*Sales!I2:I121) | E29: =IF(Sales!C29="East",Sales!H29,"") | F29: =IF(Sales!C29="East",Sales!H29,"")
E30: =IF(Sales!C30="East",Sales!H30,"") | F30: =IF(Sales!C30="East",Sales!H30,"")
E31: =IF(Sales!C31="East",Sales!H31,"") | F31: =IF(Sales!C31="East",Sales!H31,"")
E32: =IF(Sales!C32="East",Sales!H32,"") | F32: =IF(Sales!C32="East",Sales!H32,"")
E33: =IF(Sales!C33="East",Sales!H33,"") | F33: =IF(Sales!C33="East",Sales!H33,"")
E34: =IF(Sales!C34="East",Sales!H34,"") | F34: =IF(Sales!C34="East",Sales!H34,"")
E35: =IF(Sales!C35="East",Sales!H35,"") | F35: =IF(Sales!C35="East",Sales!H35,"")
E36: =IF(Sales!C36="East",Sales!H36,"") | F36: =IF(Sales!C36="East",Sales!H36,"")
E37: =IF(Sales!C37="East",Sales!H37,"") | F37: =IF(Sales!C37="East",Sales!H37,"")
E38: =IF(Sales!C38="East",Sales!H38,"") | F38: =IF(Sales!C38="East",Sales!H38,"")
E39: =IF(Sales!C39="East",Sales!H39,"") | F39: =IF(Sales!C39="East",Sales!H39,"")
E40: =IF(Sales!C40="East",Sales!H40,"") | F40: =IF(Sales!C40="East",Sales!H40,"")
...

Sheet Logical
A1: Logical Formula Examples
A3: Formula | B3: Meaning | C3: Row 2 Result
A4: =IF(Sales!H2>15,"Bulk","Normal") | B4: Classifies an order by Units. | C4: =IF(Sales!H2>15,"Bulk","Normal")
A5: =IF(AND(Sales!H2>10,Sales!J2>0),"Bulk Discount","") | B5: Requires more than 10 Units and a discount. | C5: =IF(AND(Sales!H2>10,Sales!J2>0),"Bulk Discount","")
A6: =IF(OR(Sales!C2="North",Sales!C2="South"),"N/S","E/W") | B6: Groups regions into North/South or East/West. | C6: =IF(OR(Sales!C2="North",Sales!C2="South"),"N/S","E/W")
A7: =IFS(Sales!H2>20,"High",Sales!H2>10,"Medium",TRUE,"Low") | B7: Uses nested IF because this Excel version may not support IFS. | C7: =IF(Sales!H2>20,"High",IF(Sales!H2>10,"Medium","Low"))
A8: =IF(Sales!H2>20,"High",IF(Sales!H2>10,"Medium","Low")) | B8: Compatibility alternative to IFS. | C8: =IF(Sales!H2>20,"High",IF(Sales!H2>10,"Medium","Low"))
A9: =SWITCH(Sales!E2,"Online",0.02,"Retail Store",0.05,"Partner",0.08) | B9: Uses nested IF because this Excel version may not support SWITCH. | C9: =IF(Sales!E2="Online",0.02,IF(Sales!E2="Retail Store",0.05,0.08))
A10: =IFERROR(Sales!H2/Sales!I2,0) | B10: Returns zero if the calculation errors. | C10: =IFERROR(Sales!H2/Sales!I2,0)
A11: =NOT(Sales!H2>15) | B11: Reverses a TRUE/FALSE condition. | C11: =NOT(Sales!H2>15)
A12: =XOR(Sales!C2="North",Sales!E2="Online") | B12: Uses IF/AND/OR because this Excel version may not support XOR. | C12: =IF(OR(AND(Sales!C2="North",Sales!E2<>"Online"),AND(Sales!C2<>"North",Sales!E2="Online")),TRUE,FALSE)

Sheet LogicDemo
A1: OrderID | B1: Units | C1: Discount | D1: Region | E1: Channel | F1: OrderSize | G1: BulkDiscount | H1: RegionGroup | I1: SizeUsingIF | J1: ChannelRate | K1: SafeRatio | L1: OneOfTwo
A2: =Sales!A2 | B2: =Sales!H2 | C2: =Sales!J2 | D2: =Sales!C2 | E2: =Sales!E2 | F2: =IF(B2>15,"Bulk","Normal") | G2: =IF(AND(B2>10,C2>0),"Bulk Discount","") | H2: =IF(OR(D2="North",D2="South"),"N/S","E/W") | I2: =IF(B2>20,"High",IF(B2>10,"Medium","Low")) | J2: =IF(E2="Online",0.02,IF(E2="Retail Store",0.05,0.08)) | K2: =IFERROR(B2/Sales!I2,0) | L2: =IF(OR(AND(D2="North",E2<>"Online"),AND(D2<>"North",E2="Online")),TRUE,FALSE)
A3: =Sales!A3 | B3: =Sales!H3 | C3: =Sales!J3 | D3: =Sales!C3 | E3: =Sales!E3 | F3: =IF(B3>15,"Bulk","Normal") | G3: =IF(AND(B3>10,C3>0),"Bulk Discount","") | H3: =IF(OR(D3="North",D3="South"),"N/S","E/W") | I3: =IF(B3>20,"High",IF(B3>10,"Medium","Low")) | J3: =IF(E3="Online",0.02,IF(E3="Retail Store",0.05,0.08)) | K3: =IFERROR(B3/Sales!I3,0) | L3: =IF(OR(AND(D3="North",E3<>"Online"),AND(D3<>"North",E3="Online")),TRUE,FALSE)
A4: =Sales!A4 | B4: =Sales!H4 | C4: =Sales!J4 | D4: =Sales!C4 | E4: =Sales!E4 | F4: =IF(B4>15,"Bulk","Normal") | G4: =IF(AND(B4>10,C4>0),"Bulk Discount","") | H4: =IF(OR(D4="North",D4="South"),"N/S","E/W") | I4: =IF(B4>20,"High",IF(B4>10,"Medium","Low")) | J4: =IF(E4="Online",0.02,IF(E4="Retail Store",0.05,0.08)) | K4: =IFERROR(B4/Sales!I4,0) | L4: =IF(OR(AND(D4="North",E4<>"Online"),AND(D4<>"North",E4="Online")),TRUE,FALSE)
A5: =Sales!A5 | B5: =Sales!H5 | C5: =Sales!J5 | D5: =Sales!C5 | E5: =Sales!E5 | F5: =IF(B5>15,"Bulk","Normal") | G5: =IF(AND(B5>10,C5>0),"Bulk Discount","") | H5: =IF(OR(D5="North",D5="South"),"N/S","E/W") | I5: =IF(B5>20,"High",IF(B5>10,"Medium","Low")) | J5: =IF(E5="Online",0.02,IF(E5="Retail Store",0.05,0.08)) | K5: =IFERROR(B5/Sales!I5,0) | L5: =IF(OR(AND(D5="North",E5<>"Online"),AND(D5<>"North",E5="Online")),TRUE,FALSE)
A6: =Sales!A6 | B6: =Sales!H6 | C6: =Sales!J6 | D6: =Sales!C6 | E6: =Sales!E6 | F6: =IF(B6>15,"Bulk","Normal") | G6: =IF(AND(B6>10,C6>0),"Bulk Discount","") | H6: =IF(OR(D6="North",D6="South"),"N/S","E/W") | I6: =IF(B6>20,"High",IF(B6>10,"Medium","Low")) | J6: =IF(E6="Online",0.02,IF(E6="Retail Store",0.05,0.08)) | K6: =IFERROR(B6/Sales!I6,0) | L6: =IF(OR(AND(D6="North",E6<>"Online"),AND(D6<>"North",E6="Online")),TRUE,FALSE)
A7: =Sales!A7 | B7: =Sales!H7 | C7: =Sales!J7 | D7: =Sales!C7 | E7: =Sales!E7 | F7: =IF(B7>15,"Bulk","Normal") | G7: =IF(AND(B7>10,C7>0),"Bulk Discount","") | H7: =IF(OR(D7="North",D7="South"),"N/S","E/W") | I7: =IF(B7>20,"High",IF(B7>10,"Medium","Low")) | J7: =IF(E7="Online",0.02,IF(E7="Retail Store",0.05,0.08)) | K7: =IFERROR(B7/Sales!I7,0) | L7: =IF(OR(AND(D7="North",E7<>"Online"),AND(D7<>"North",E7="Online")),TRUE,FALSE)
A8: =Sales!A8 | B8: =Sales!H8 | C8: =Sales!J8 | D8: =Sales!C8 | E8: =Sales!E8 | F8: =IF(B8>15,"Bulk","Normal") | G8: =IF(AND(B8>10,C8>0),"Bulk Discount","") | H8: =IF(OR(D8="North",D8="South"),"N/S","E/W") | I8: =IF(B8>20,"High",IF(B8>10,"Medium","Low")) | J8: =IF(E8="Online",0.02,IF(E8="Retail Store",0.05,0.08)) | K8: =IFERROR(B8/Sales!I8,0) | L8: =IF(OR(AND(D8="North",E8<>"Online"),AND(D8<>"North",E8="Online")),TRUE,FALSE)
A9: =Sales!A9 | B9: =Sales!H9 | C9: =Sales!J9 | D9: =Sales!C9 | E9: =Sales!E9 | F9: =IF(B9>15,"Bulk","Normal") | G9: =IF(AND(B9>10,C9>0),"Bulk Discount","") | H9: =IF(OR(D9="North",D9="South"),"N/S","E/W") | I9: =IF(B9>20,"High",IF(B9>10,"Medium","Low")) | J9: =IF(E9="Online",0.02,IF(E9="Retail Store",0.05,0.08)) | K9: =IFERROR(B9/Sales!I9,0) | L9: =IF(OR(AND(D9="North",E9<>"Online"),AND(D9<>"North",E9="Online")),TRUE,FALSE)
A10: =Sales!A10 | B10: =Sales!H10 | C10: =Sales!J10 | D10: =Sales!C10 | E10: =Sales!E10 | F10: =IF(B10>15,"Bulk","Normal") | G10: =IF(AND(B10>10,C10>0),"Bulk Discount","") | H10: =IF(OR(D10="North",D10="South"),"N/S","E/W") | I10: =IF(B10>20,"High",IF(B10>10,"Medium","Low")) | J10: =IF(E10="Online",0.02,IF(E10="Retail Store",0.05,0.08)) | K10: =IFERROR(B10/Sales!I10,0) | L10: =IF(OR(AND(D10="North",E10<>"Online"),AND(D10<>"North",E10="Online")),TRUE,FALSE)
A11: =Sales!A11 | B11: =Sales!H11 | C11: =Sales!J11 | D11: =Sales!C11 | E11: =Sales!E11 | F11: =IF(B11>15,"Bulk","Normal") | G11: =IF(AND(B11>10,C11>0),"Bulk Discount","") | H11: =IF(OR(D11="North",D11="South"),"N/S","E/W") | I11: =IF(B11>20,"High",IF(B11>10,"Medium","Low")) | J11: =IF(E11="Online",0.02,IF(E11="Retail Store",0.05,0.08)) | K11: =IFERROR(B11/Sales!I11,0) | L11: =IF(OR(AND(D11="North",E11<>"Online"),AND(D11<>"North",E11="Online")),TRUE,FALSE)
A12: =Sales!A12 | B12: =Sales!H12 | C12: =Sales!J12 | D12: =Sales!C12 | E12: =Sales!E12 | F12: =IF(B12>15,"Bulk","Normal") | G12: =IF(AND(B12>10,C12>0),"Bulk Discount","") | H12: =IF(OR(D12="North",D12="South"),"N/S","E/W") | I12: =IF(B12>20,"High",IF(B12>10,"Medium","Low")) | J12: =IF(E12="Online",0.02,IF(E12="Retail Store",0.05,0.08)) | K12: =IFERROR(B12/Sales!I12,0) | L12: =IF(OR(AND(D12="North",E12<>"Online"),AND(D12<>"North",E12="Online")),TRUE,FALSE)
A13: =Sales!A13 | B13: =Sales!H13 | C13: =Sales!J13 | D13: =Sales!C13 | E13: =Sales!E13 | F13: =IF(B13>15,"Bulk","Normal") | G13: =IF(AND(B13>10,C13>0),"Bulk Discount","") | H13: =IF(OR(D13="North",D13="South"),"N/S","E/W") | I13: =IF(B13>20,"High",IF(B13>10,"Medium","Low")) | J13: =IF(E13="Online",0.02,IF(E13="Retail Store",0.05,0.08)) | K13: =IFERROR(B13/Sales!I13,0) | L13: =IF(OR(AND(D13="North",E13<>"Online"),AND(D13<>"North",E13="Online")),TRUE,FALSE)
... A121: =Sales!A121 | B121: =Sales!H121 | C121: =Sales!J121 | D121: =Sales!C121 | E121: =Sales!E121 | F121: =IF(B121>15,"Bulk","Normal") | G121: =IF(AND(B121>10,C121>0),"Bulk Discount","") | H121: =IF(OR(D121="North",D121="South"),"N/S","E/W") | I121: =IF(B121>20,"High",IF(B121>10,"Medium","Low")) | J121: =IF(E121="Online",0.02,IF(E121="Retail Store",0.05,0.08)) | K121: =IFERROR(B121/Sales!I121,0) | L121: =IF(OR(AND(D121="North",E121<>"Online"),AND(D121<>"North",E121="Online")),TRUE,FALSE)

Sheet Lookup
A1: Lookup & Reference Examples
A2: Formula | B2: Meaning | C2: Row 2 Result
A3: =VLOOKUP(Sales!G2,Products!$A$2:$D$10,4,FALSE) | B3: Returns UnitCost using the product name. | C3: =VLOOKUP(Sales!G2,Products!$A$2:$D$10,4,FALSE)
A4: =XLOOKUP(Sales!G2,Products!$A$2:$A$10,Products!$D$2:$D$10) | B4: Modern alternative to VLOOKUP; shown for reference. | C4: =INDEX(Products!$D$2:$D$10,MATCH(Sales!G2,Products!$A$2:$A$10,0))
A5: =INDEX(Products!$D$2:$D$10,MATCH(Sales!G2,Products!$A$2:$A$10,0)) | B5: Compatible exact-match lookup for UnitCost. | C5: =INDEX(Products!$D$2:$D$10,MATCH(Sales!G2,Products!$A$2:$A$10,0))
A6: =HLOOKUP("Laptop Pro 14",Products!$A$1:$I$4,4,FALSE) | B6: Searches horizontally; included as a reference example. | C6: =IFERROR(INDEX(Products!$D$2:$D$10,MATCH(Sales!G2,Products!$A$2:$A$10,0)),0)
A7: =LOOKUP(Sales!G2,Products!$A$2:$A$10,Products!$D$2:$D$10) | B7: Approximate lookup; the lookup list must be sorted. | C7: =INDEX(Products!$D$2:$D$10,MATCH(Sales!G2,Products!$A$2:$A$10,0))
A8: =CHOOSE(2,"Online","Retail Store","Partner") | B8: Returns the selected item by position. | C8: =CHOOSE(2,"Online","Retail Store","Partner")
A9: =OFFSET(Products!A1,1,3) | B9: Returns a reference offset from a starting cell. | C9: =IFERROR(INDEX(Products!$D$2:$D$10,MATCH(Sales!G2,Products!$A$2:$A$10,0)),0)
A10: =INDIRECT("Products!D2") | B10: Converts text into a cell reference. | C10: =IFERROR(INDEX(Products!$D$2:$D$10,MATCH(Sales!G2,Products!$A$2:$A$10,0)),0)
A11: =XLOOKUP(Sales!D2,Targets!$B$2:$B$9,Targets!$C$2:$C$9) | B11: Returns MonthlyTarget for a salesperson. | C11: =IFERROR(INDEX(Targets!$C$2:$C$9,MATCH(Sales!D2,Targets!$B$2:$B$9,0)),0)

Sheet LookupDemo
A1: OrderID | B1: Product | C1: UnitCost | D1: Salesperson | E1: MonthlyTarget | F1: ProductLookupMethod | G1: TargetLookupMethod
A2: =Sales!A2 | B2: =Sales!G2 | C2: =IFERROR(INDEX(Products!$D$2:$D$10,MATCH(B2,Products!$A$2:$A$10,0)),0) | D2: =Sales!D2 | E2: =IFERROR(INDEX(Targets!$C$2:$C$9,MATCH(D2,Targets!$B$2:$B$9,0)),0) | F2: INDEX/MATCH | G2: INDEX/MATCH
A3: =Sales!A3 | B3: =Sales!G3 | C3: =IFERROR(INDEX(Products!$D$2:$D$10,MATCH(B3,Products!$A$2:$A$10,0)),0) | D3: =Sales!D3 | E3: =IFERROR(INDEX(Targets!$C$2:$C$9,MATCH(D3,Targets!$B$2:$B$9,0)),0) | F3: INDEX/MATCH | G3: INDEX/MATCH
A4: =Sales!A4 | B4: =Sales!G4 | C4: =IFERROR(INDEX(Products!$D$2:$D$10,MATCH(B4,Products!$A$2:$A$10,0)),0) | D4: =Sales!D4 | E4: =IFERROR(INDEX(Targets!$C$2:$C$9,MATCH(D4,Targets!$B$2:$B$9,0)),0) | F4: INDEX/MATCH | G4: INDEX/MATCH
A5: =Sales!A5 | B5: =Sales!G5 | C5: =IFERROR(INDEX(Products!$D$2:$D$10,MATCH(B5,Products!$A$2:$A$10,0)),0) | D5: =Sales!D5 | E5: =IFERROR(INDEX(Targets!$C$2:$C$9,MATCH(D5,Targets!$B$2:$B$9,0)),0) | F5: INDEX/MATCH | G5: INDEX/MATCH
A6: =Sales!A6 | B6: =Sales!G6 | C6: =IFERROR(INDEX(Products!$D$2:$D$10,MATCH(B6,Products!$A$2:$A$10,0)),0) | D6: =Sales!D6 | E6: =IFERROR(INDEX(Targets!$C$2:$C$9,MATCH(D6,Targets!$B$2:$B$9,0)),0) | F6: INDEX/MATCH | G6: INDEX/MATCH
A7: =Sales!A7 | B7: =Sales!G7 | C7: =IFERROR(INDEX(Products!$D$2:$D$10,MATCH(B7,Products!$A$2:$A$10,0)),0) | D7: =Sales!D7 | E7: =IFERROR(INDEX(Targets!$C$2:$C$9,MATCH(D7,Targets!$B$2:$B$9,0)),0) | F7: INDEX/MATCH | G7: INDEX/MATCH
A8: =Sales!A8 | B8: =Sales!G8 | C8: =IFERROR(INDEX(Products!$D$2:$D$10,MATCH(B8,Products!$A$2:$A$10,0)),0) | D8: =Sales!D8 | E8: =IFERROR(INDEX(Targets!$C$2:$C$9,MATCH(D8,Targets!$B$2:$B$9,0)),0) | F8: INDEX/MATCH | G8: INDEX/MATCH
A9: =Sales!A9 | B9: =Sales!G9 | C9: =IFERROR(INDEX(Products!$D$2:$D$10,MATCH(B9,Products!$A$2:$A$10,0)),0) | D9: =Sales!D9 | E9: =IFERROR(INDEX(Targets!$C$2:$C$9,MATCH(D9,Targets!$B$2:$B$9,0)),0) | F9: INDEX/MATCH | G9: INDEX/MATCH
A10: =Sales!A10 | B10: =Sales!G10 | C10: =IFERROR(INDEX(Products!$D$2:$D$10,MATCH(B10,Products!$A$2:$A$10,0)),0) | D10: =Sales!D10 | E10: =IFERROR(INDEX(Targets!$C$2:$C$9,MATCH(D10,Targets!$B$2:$B$9,0)),0) | F10: INDEX/MATCH | G10: INDEX/MATCH
A11: =Sales!A11 | B11: =Sales!G11 | C11: =IFERROR(INDEX(Products!$D$2:$D$10,MATCH(B11,Products!$A$2:$A$10,0)),0) | D11: =Sales!D11 | E11: =IFERROR(INDEX(Targets!$C$2:$C$9,MATCH(D11,Targets!$B$2:$B$9,0)),0) | F11: INDEX/MATCH | G11: INDEX/MATCH
A12: =Sales!A12 | B12: =Sales!G12 | C12: =IFERROR(INDEX(Products!$D$2:$D$10,MATCH(B12,Products!$A$2:$A$10,0)),0) | D12: =Sales!D12 | E12: =IFERROR(INDEX(Targets!$C$2:$C$9,MATCH(D12,Targets!$B$2:$B$9,0)),0) | F12: INDEX/MATCH | G12: INDEX/MATCH
A13: =Sales!A13 | B13: =Sales!G13 | C13: =IFERROR(INDEX(Products!$D$2:$D$10,MATCH(B13,Products!$A$2:$A$10,0)),0) | D13: =Sales!D13 | E13: =IFERROR(INDEX(Targets!$C$2:$C$9,MATCH(D13,Targets!$B$2:$B$9,0)),0) | F13: INDEX/MATCH | G13: INDEX/MATCH
... A121: =Sales!A121 | B121: =Sales!G121 | C121: =IFERROR(INDEX(Products!$D$2:$D$10,MATCH(B121,Products!$A$2:$A$10,0)),0) | D121: =Sales!D121 | E121: =IFERROR(INDEX(Targets!$C$2:$C$9,MATCH(D121,Targets!$B$2:$B$9,0)),0) | F121: INDEX/MATCH | G121: INDEX/MATCH

Sheet DateTime
A1: Date & Time Formula Examples
A2: Formula | B2: Meaning | C2: Row 2 Result
A3: =YEAR(Sales!B2) | B3: Returns the order year. | C3: =YEAR(Sales!B2)
A4: =MONTH(Sales!B2) | B4: Returns the order month number. | C4: =MONTH(Sales!B2)
A5: =DAY(Sales!B2) | B5: Returns the day of the month. | C5: =DAY(Sales!B2)
A6: =WEEKNUM(Sales!B2) | B6: Returns the week number. | C6: =WEEKNUM(Sales!B2)
A7: =TEXT(Sales!B2,"mmm") | B7: Displays the abbreviated month. | C7: =TEXT(Sales!B2,"mmm")
A8: =TEXT(Sales!B2,"mmm-yy") | B8: Displays month and year. | C8: =TEXT(Sales!B2,"mmm-yy")
A9: =EOMONTH(Sales!B2,0) | B9: Returns the last day of the order month. | C9: =EOMONTH(Sales!B2,0)
A10: =EDATE(Sales!B2,1) | B10: Returns one month after the order date. | C10: =EDATE(Sales!B2,1)
A11: =WEEKDAY(Sales!B2,2) | B11: Returns Monday as 1 through Sunday as 7. | C11: =WEEKDAY(Sales!B2,2)
A12: =NETWORKDAYS(Sales!B2,TODAY()) | B12: Counts weekdays from order date to today. | C12: =NETWORKDAYS(Sales!B2,TODAY())
A13: =DATEDIF(Sales!B2,TODAY(),"m") | B13: Counts complete months from order date to today. | C13: =DATEDIF(Sales!B2,TODAY(),"m")
A14: =TODAY() | B14: Returns today’s date. | C14: =TODAY()
A15: =NOW() | B15: Returns the current date and time. | C15: =NOW()

Sheet DateTimeDemo
A1: OrderID | B1: OrderDate | C1: Year | D1: Month | E1: Day | F1: WeekNum | G1: MonthName | H1: MonthYear | I1: MonthEnd | J1: NextMonth | K1: Weekday | L1: WorkdaysToToday | M1: MonthsToToday
A2: =Sales!A2 | B2: =Sales!B2 | C2: =YEAR(B2) | D2: =MONTH(B2) | E2: =DAY(B2) | F2: =WEEKNUM(B2) | G2: =TEXT(B2,"mmm") | H2: =TEXT(B2,"mmm-yy") | I2: =EOMONTH(B2,0) | J2: =EDATE(B2,1) | K2: =WEEKDAY(B2,2) | L2: =NETWORKDAYS(B2,TODAY()) | M2: =IFERROR(DATEDIF(B2,TODAY(),"m"),0)
A3: =Sales!A3 | B3: =Sales!B3 | C3: =YEAR(B3) | D3: =MONTH(B3) | E3: =DAY(B3) | F3: =WEEKNUM(B3) | G3: =TEXT(B3,"mmm") | H3: =TEXT(B3,"mmm-yy") | I3: =EOMONTH(B3,0) | J3: =EDATE(B3,1) | K3: =WEEKDAY(B3,2) | L3: =NETWORKDAYS(B3,TODAY()) | M3: =IFERROR(DATEDIF(B3,TODAY(),"m"),0)
A4: =Sales!A4 | B4: =Sales!B4 | C4: =YEAR(B4) | D4: =MONTH(B4) | E4: =DAY(B4) | F4: =WEEKNUM(B4) | G4: =TEXT(B4,"mmm") | H4: =TEXT(B4,"mmm-yy") | I4: =EOMONTH(B4,0) | J4: =EDATE(B4,1) | K4: =WEEKDAY(B4,2) | L4: =NETWORKDAYS(B4,TODAY()) | M4: =IFERROR(DATEDIF(B4,TODAY(),"m"),0)
A5: =Sales!A5 | B5: =Sales!B5 | C5: =YEAR(B5) | D5: =MONTH(B5) | E5: =DAY(B5) | F5: =WEEKNUM(B5) | G5: =TEXT(B5,"mmm") | H5: =TEXT(B5,"mmm-yy") | I5: =EOMONTH(B5,0) | J5: =EDATE(B5,1) | K5: =WEEKDAY(B5,2) | L5: =NETWORKDAYS(B5,TODAY()) | M5: =IFERROR(DATEDIF(B5,TODAY(),"m"),0)
A6: =Sales!A6 | B6: =Sales!B6 | C6: =YEAR(B6) | D6: =MONTH(B6) | E6: =DAY(B6) | F6: =WEEKNUM(B6) | G6: =TEXT(B6,"mmm") | H6: =TEXT(B6,"mmm-yy") | I6: =EOMONTH(B6,0) | J6: =EDATE(B6,1) | K6: =WEEKDAY(B6,2) | L6: =NETWORKDAYS(B6,TODAY()) | M6: =IFERROR(DATEDIF(B6,TODAY(),"m"),0)
A7: =Sales!A7 | B7: =Sales!B7 | C7: =YEAR(B7) | D7: =MONTH(B7) | E7: =DAY(B7) | F7: =WEEKNUM(B7) | G7: =TEXT(B7,"mmm") | H7: =TEXT(B7,"mmm-yy") | I7: =EOMONTH(B7,0) | J7: =EDATE(B7,1) | K7: =WEEKDAY(B7,2) | L7: =NETWORKDAYS(B7,TODAY()) | M7: =IFERROR(DATEDIF(B7,TODAY(),"m"),0)
A8: =Sales!A8 | B8: =Sales!B8 | C8: =YEAR(B8) | D8: =MONTH(B8) | E8: =DAY(B8) | F8: =WEEKNUM(B8) | G8: =TEXT(B8,"mmm") | H8: =TEXT(B8,"mmm-yy") | I8: =EOMONTH(B8,0) | J8: =EDATE(B8,1) | K8: =WEEKDAY(B8,2) | L8: =NETWORKDAYS(B8,TODAY()) | M8: =IFERROR(DATEDIF(B8,TODAY(),"m"),0)
A9: =Sales!A9 | B9: =Sales!B9 | C9: =YEAR(B9) | D9: =MONTH(B9) | E9: =DAY(B9) | F9: =WEEKNUM(B9) | G9: =TEXT(B9,"mmm") | H9: =TEXT(B9,"mmm-yy") | I9: =EOMONTH(B9,0) | J9: =EDATE(B9,1) | K9: =WEEKDAY(B9,2) | L9: =NETWORKDAYS(B9,TODAY()) | M9: =IFERROR(DATEDIF(B9,TODAY(),"m"),0)
A10: =Sales!A10 | B10: =Sales!B10 | C10: =YEAR(B10) | D10: =MONTH(B10) | E10: =DAY(B10) | F10: =WEEKNUM(B10) | G10: =TEXT(B10,"mmm") | H10: =TEXT(B10,"mmm-yy") | I10: =EOMONTH(B10,0) | J10: =EDATE(B10,1) | K10: =WEEKDAY(B10,2) | L10: =NETWORKDAYS(B10,TODAY()) | M10: =IFERROR(DATEDIF(B10,TODAY(),"m"),0)
A11: =Sales!A11 | B11: =Sales!B11 | C11: =YEAR(B11) | D11: =MONTH(B11) | E11: =DAY(B11) | F11: =WEEKNUM(B11) | G11: =TEXT(B11,"mmm") | H11: =TEXT(B11,"mmm-yy") | I11: =EOMONTH(B11,0) | J11: =EDATE(B11,1) | K11: =WEEKDAY(B11,2) | L11: =NETWORKDAYS(B11,TODAY()) | M11: =IFERROR(DATEDIF(B11,TODAY(),"m"),0)
A12: =Sales!A12 | B12: =Sales!B12 | C12: =YEAR(B12) | D12: =MONTH(B12) | E12: =DAY(B12) | F12: =WEEKNUM(B12) | G12: =TEXT(B12,"mmm") | H12: =TEXT(B12,"mmm-yy") | I12: =EOMONTH(B12,0) | J12: =EDATE(B12,1) | K12: =WEEKDAY(B12,2) | L12: =NETWORKDAYS(B12,TODAY()) | M12: =IFERROR(DATEDIF(B12,TODAY(),"m"),0)
A13: =Sales!A13 | B13: =Sales!B13 | C13: =YEAR(B13) | D13: =MONTH(B13) | E13: =DAY(B13) | F13: =WEEKNUM(B13) | G13: =TEXT(B13,"mmm") | H13: =TEXT(B13,"mmm-yy") | I13: =EOMONTH(B13,0) | J13: =EDATE(B13,1) | K13: =WEEKDAY(B13,2) | L13: =NETWORKDAYS(B13,TODAY()) | M13: =IFERROR(DATEDIF(B13,TODAY(),"m"),0)
... A121: =Sales!A121 | B121: =Sales!B121 | C121: =YEAR(B121) | D121: =MONTH(B121) | E121: =DAY(B121) | F121: =WEEKNUM(B121) | G121: =TEXT(B121,"mmm") | H121: =TEXT(B121,"mmm-yy") | I121: =EOMONTH(B121,0) | J121: =EDATE(B121,1) | K121: =WEEKDAY(B121,2) | L121: =NETWORKDAYS(B121,TODAY()) | M121: =IFERROR(DATEDIF(B121,TODAY(),"m"),0)

Sheet Text
A1: Text Formula Examples
A2: Formula | B2: Meaning | C2: Row 2 Result
A3: =UPPER(Sales!D2) | B3: Converts the salesperson name to uppercase. | C3: =UPPER(Sales!D2)
A4: =LOWER(Sales!D2) | B4: Converts the salesperson name to lowercase. | C4: =LOWER(Sales!D2)
A5: =PROPER(Sales!D2) | B5: Capitalizes each word in the salesperson name. | C5: =PROPER(Sales!D2)
A6: =LEFT(Sales!A2,3) | B6: Returns the first three OrderID characters. | C6: =LEFT(Sales!A2,3)
A7: =RIGHT(Sales!A2,4) | B7: Returns the last four OrderID characters. | C7: =RIGHT(Sales!A2,4)
A8: =MID(Sales!A2,5,4) | B8: Extracts four characters starting at position five. | C8: =MID(Sales!A2,5,4)
A9: =LEN(Sales!G2) | B9: Counts characters in the product name. | C9: =LEN(Sales!G2)
A10: =TRIM(Sales!G2) | B10: Removes extra spaces from the product name. | C10: =TRIM(Sales!G2)
A11: =CONCAT(Sales!C2,"-",Sales!D2) | B11: Combines Region and Salesperson. | C11: =Sales!C2&"-"&Sales!D2
A12: =TEXTJOIN("-",TRUE,Sales!C2,Sales!E2) | B12: Combines Region and Channel. | C12: =Sales!C2&"-"&Sales!E2
A13: =SUBSTITUTE(Sales!A2,"ORD-","") | B13: Removes the ORD- prefix. | C13: =SUBSTITUTE(Sales!A2,"ORD-","")
A14: =FIND("-",Sales!A2) | B14: Finds the hyphen position; case-sensitive. | C14: =FIND("-",Sales!A2)
A15: =SEARCH("ord",Sales!A2) | B15: Finds text without case sensitivity. | C15: =SEARCH("ord",Sales!A2)
A16: =TEXTBEFORE(Sales!A2,"-") | B16: Modern way to return text before a hyphen. | C16: =LEFT(Sales!A2,FIND("-",Sales!A2)-1)
A17: =TEXTAFTER(Sales!A2,"-") | B17: Modern way to return text after a hyphen. | C17: =MID(Sales!A2,FIND("-",Sales!A2)+1,LEN(Sales!A2))
A18: =VALUE(TEXTAFTER(Sales!A2,"-")) | B18: Converts the extracted OrderID text to a number. | C18: =VALUE(MID(Sales!A2,FIND("-",Sales!A2)+1,LEN(Sales!A2)))

Sheet TextDemo
A1: OrderID | B1: Salesperson | C1: Product | D1: Region | E1: Channel | F1: UpperName | G1: LowerName | H1: ProperName | I1: OrderPrefix | J1: OrderNumberText | K1: ProductLength | L1: CleanProduct | M1: RegionSalesperson | N1: RegionChannel | O1: OrderNumber
A2: =Sales!A2 | B2: =Sales!D2 | C2: =Sales!G2 | D2: =Sales!C2 | E2: =Sales!E2 | F2: =UPPER(B2) | G2: =LOWER(B2) | H2: =PROPER(B2) | I2: =LEFT(A2,3) | J2: =RIGHT(A2,4) | K2: =LEN(C2) | L2: =TRIM(C2) | M2: =D2&"-"&B2 | N2: =D2&"-"&E2 | O2: =VALUE(MID(A2,FIND("-",A2)+1,LEN(A2)))
A3: =Sales!A3 | B3: =Sales!D3 | C3: =Sales!G3 | D3: =Sales!C3 | E3: =Sales!E3 | F3: =UPPER(B3) | G3: =LOWER(B3) | H3: =PROPER(B3) | I3: =LEFT(A3,3) | J3: =RIGHT(A3,4) | K3: =LEN(C3) | L3: =TRIM(C3) | M3: =D3&"-"&B3 | N3: =D3&"-"&E3 | O3: =VALUE(MID(A3,FIND("-",A3)+1,LEN(A3)))
A4: =Sales!A4 | B4: =Sales!D4 | C4: =Sales!G4 | D4: =Sales!C4 | E4: =Sales!E4 | F4: =UPPER(B4) | G4: =LOWER(B4) | H4: =PROPER(B4) | I4: =LEFT(A4,3) | J4: =RIGHT(A4,4) | K4: =LEN(C4) | L4: =TRIM(C4) | M4: =D4&"-"&B4 | N4: =D4&"-"&E4 | O4: =VALUE(MID(A4,FIND("-",A4)+1,LEN(A4)))
A5: =Sales!A5 | B5: =Sales!D5 | C5: =Sales!G5 | D5: =Sales!C5 | E5: =Sales!E5 | F5: =UPPER(B5) | G5: =LOWER(B5) | H5: =PROPER(B5) | I5: =LEFT(A5,3) | J5: =RIGHT(A5,4) | K5: =LEN(C5) | L5: =TRIM(C5) | M5: =D5&"-"&B5 | N5: =D5&"-"&E5 | O5: =VALUE(MID(A5,FIND("-",A5)+1,LEN(A5)))
A6: =Sales!A6 | B6: =Sales!D6 | C6: =Sales!G6 | D6: =Sales!C6 | E6: =Sales!E6 | F6: =UPPER(B6) | G6: =LOWER(B6) | H6: =PROPER(B6) | I6: =LEFT(A6,3) | J6: =RIGHT(A6,4) | K6: =LEN(C6) | L6: =TRIM(C6) | M6: =D6&"-"&B6 | N6: =D6&"-"&E6 | O6: =VALUE(MID(A6,FIND("-",A6)+1,LEN(A6)))
A7: =Sales!A7 | B7: =Sales!D7 | C7: =Sales!G7 | D7: =Sales!C7 | E7: =Sales!E7 | F7: =UPPER(B7) | G7: =LOWER(B7) | H7: =PROPER(B7) | I7: =LEFT(A7,3) | J7: =RIGHT(A7,4) | K7: =LEN(C7) | L7: =TRIM(C7) | M7: =D7&"-"&B7 | N7: =D7&"-"&E7 | O7: =VALUE(MID(A7,FIND("-",A7)+1,LEN(A7)))
A8: =Sales!A8 | B8: =Sales!D8 | C8: =Sales!G8 | D8: =Sales!C8 | E8: =Sales!E8 | F8: =UPPER(B8) | G8: =LOWER(B8) | H8: =PROPER(B8) | I8: =LEFT(A8,3) | J8: =RIGHT(A8,4) | K8: =LEN(C8) | L8: =TRIM(C8) | M8: =D8&"-"&B8 | N8: =D8&"-"&E8 | O8: =VALUE(MID(A8,FIND("-",A8)+1,LEN(A8)))
A9: =Sales!A9 | B9: =Sales!D9 | C9: =Sales!G9 | D9: =Sales!C9 | E9: =Sales!E9 | F9: =UPPER(B9) | G9: =LOWER(B9) | H9: =PROPER(B9) | I9: =LEFT(A9,3) | J9: =RIGHT(A9,4) | K9: =LEN(C9) | L9: =TRIM(C9) | M9: =D9&"-"&B9 | N9: =D9&"-"&E9 | O9: =VALUE(MID(A9,FIND("-",A9)+1,LEN(A9)))
A10: =Sales!A10 | B10: =Sales!D10 | C10: =Sales!G10 | D10: =Sales!C10 | E10: =Sales!E10 | F10: =UPPER(B10) | G10: =LOWER(B10) | H10: =PROPER(B10) | I10: =LEFT(A10,3) | J10: =RIGHT(A10,4) | K10: =LEN(C10) | L10: =TRIM(C10) | M10: =D10&"-"&B10 | N10: =D10&"-"&E10 | O10: =VALUE(MID(A10,FIND("-",A10)+1,LEN(A10)))
A11: =Sales!A11 | B11: =Sales!D11 | C11: =Sales!G11 | D11: =Sales!C11 | E11: =Sales!E11 | F11: =UPPER(B11) | G11: =LOWER(B11) | H11: =PROPER(B11) | I11: =LEFT(A11,3) | J11: =RIGHT(A11,4) | K11: =LEN(C11) | L11: =TRIM(C11) | M11: =D11&"-"&B11 | N11: =D11&"-"&E11 | O11: =VALUE(MID(A11,FIND("-",A11)+1,LEN(A11)))
A12: =Sales!A12 | B12: =Sales!D12 | C12: =Sales!G12 | D12: =Sales!C12 | E12: =Sales!E12 | F12: =UPPER(B12) | G12: =LOWER(B12) | H12: =PROPER(B12) | I12: =LEFT(A12,3) | J12: =RIGHT(A12,4) | K12: =LEN(C12) | L12: =TRIM(C12) | M12: =D12&"-"&B12 | N12: =D12&"-"&E12 | O12: =VALUE(MID(A12,FIND("-",A12)+1,LEN(A12)))
A13: =Sales!A13 | B13: =Sales!D13 | C13: =Sales!G13 | D13: =Sales!C13 | E13: =Sales!E13 | F13: =UPPER(B13) | G13: =LOWER(B13) | H13: =PROPER(B13) | I13: =LEFT(A13,3) | J13: =RIGHT(A13,4) | K13: =LEN(C13) | L13: =TRIM(C13) | M13: =D13&"-"&B13 | N13: =D13&"-"&E13 | O13: =VALUE(MID(A13,FIND("-",A13)+1,LEN(A13)))
... A121: =Sales!A121 | B121: =Sales!D121 | C121: =Sales!G121 | D121: =Sales!C121 | E121: =Sales!E121 | F121: =UPPER(B121) | G121: =LOWER(B121) | H121: =PROPER(B121) | I121: =LEFT(A121,3) | J121: =RIGHT(A121,4) | K121: =LEN(C121) | L121: =TRIM(C121) | M121: =D121&"-"&B121 | N121: =D121&"-"&E121 | O121: =VALUE(MID(A121,FIND("-",A121)+1,LEN(A121)))

Sheet SalespersonTargets
A1: Salesperson | B1: MonthlyTarget
A2: =Targets!B2 | B2: =IFERROR(INDEX(Targets!$C$2:$C$9,MATCH(A2,Targets!$B$2:$B$9,0)),0)
A3: =Targets!B3 | B3: =IFERROR(INDEX(Targets!$C$2:$C$9,MATCH(A3,Targets!$B$2:$B$9,0)),0)
A4: =Targets!B4 | B4: =IFERROR(INDEX(Targets!$C$2:$C$9,MATCH(A4,Targets!$B$2:$B$9,0)),0)
A5: =Targets!B5 | B5: =IFERROR(INDEX(Targets!$C$2:$C$9,MATCH(A5,Targets!$B$2:$B$9,0)),0)
A6: =Targets!B6 | B6: =IFERROR(INDEX(Targets!$C$2:$C$9,MATCH(A6,Targets!$B$2:$B$9,0)),0)
A7: =Targets!B7 | B7: =IFERROR(INDEX(Targets!$C$2:$C$9,MATCH(A7,Targets!$B$2:$B$9,0)),0)
A8: =Targets!B8 | B8: =IFERROR(INDEX(Targets!$C$2:$C$9,MATCH(A8,Targets!$B$2:$B$9,0)),0)
A9: =Targets!B9 | B9: =IFERROR(INDEX(Targets!$C$2:$C$9,MATCH(A9,Targets!$B$2:$B$9,0)),0)

Sheet SalespersonTargetRegion
A1: Salesperson | B1: Region | C1: MonthlyTarget
A2: =Targets!B2 | B2: =IFERROR(INDEX(Targets!$A$2:$A$9,MATCH(A2,Targets!$B$2:$B$9,0)),"") | C2: =IFERROR(INDEX(Targets!$C$2:$C$9,MATCH(A2,Targets!$B$2:$B$9,0)),0)
A3: =Targets!B3 | B3: =IFERROR(INDEX(Targets!$A$2:$A$9,MATCH(A3,Targets!$B$2:$B$9,0)),"") | C3: =IFERROR(INDEX(Targets!$C$2:$C$9,MATCH(A3,Targets!$B$2:$B$9,0)),0)
A4: =Targets!B4 | B4: =IFERROR(INDEX(Targets!$A$2:$A$9,MATCH(A4,Targets!$B$2:$B$9,0)),"") | C4: =IFERROR(INDEX(Targets!$C$2:$C$9,MATCH(A4,Targets!$B$2:$B$9,0)),0)
A5: =Targets!B5 | B5: =IFERROR(INDEX(Targets!$A$2:$A$9,MATCH(A5,Targets!$B$2:$B$9,0)),"") | C5: =IFERROR(INDEX(Targets!$C$2:$C$9,MATCH(A5,Targets!$B$2:$B$9,0)),0)
A6: =Targets!B6 | B6: =IFERROR(INDEX(Targets!$A$2:$A$9,MATCH(A6,Targets!$B$2:$B$9,0)),"") | C6: =IFERROR(INDEX(Targets!$C$2:$C$9,MATCH(A6,Targets!$B$2:$B$9,0)),0)
A7: =Targets!B7 | B7: =IFERROR(INDEX(Targets!$A$2:$A$9,MATCH(A7,Targets!$B$2:$B$9,0)),"") | C7: =IFERROR(INDEX(Targets!$C$2:$C$9,MATCH(A7,Targets!$B$2:$B$9,0)),0)
A8: =Targets!B8 | B8: =IFERROR(INDEX(Targets!$A$2:$A$9,MATCH(A8,Targets!$B$2:$B$9,0)),"") | C8: =IFERROR(INDEX(Targets!$C$2:$C$9,MATCH(A8,Targets!$B$2:$B$9,0)),0)
A9: =Targets!B9 | B9: =IFERROR(INDEX(Targets!$A$2:$A$9,MATCH(A9,Targets!$B$2:$B$9,0)),"") | C9: =IFERROR(INDEX(Targets!$C$2:$C$9,MATCH(A9,Targets!$B$2:$B$9,0)),0)
